Workbook
Name Criticidad: '[1]Tablas valores'!$B$2:$B$4
Name estadocdp: '[1]Tablas valores'!$D$2:$D$5
Name tipocdp: '[1]Tablas valores'!$C$2:$C$3
Name Tipoejecucion: '[1]Tablas valores'!$A$2:$A$3

Sheet Resumen Avance
B3: Módulo | C3: Casos de prueba | D3: OK | E3: KO | F3: Pendientes | G3: Avance
B4: Facturas SAP NI | C4: ='Facturas SAP NI'!T80 -> 20 | D4: ='Facturas SAP NI'!T79 -> 0 | E4: ='Facturas SAP NI'!T78 -> 0 | F4: ='Facturas SAP NI'!T77 -> 20 | G4: ='Facturas SAP NI'!T76 -> 0
B5: Facturas GNCOM | C5: ='Facturas GNCOM'!P43 -> 37 | D5: ='Facturas GNCOM'!P42 -> 0 | E5: ='Facturas GNCOM'!P41 -> 0 | F5: ='Facturas GNCOM'!P40 -> 37 | G5: ='Facturas GNCOM'!P39 -> 0
B6: Cartas GNCOM | C6: ='Cartas GNCOM'!P23 -> 17 | D6: ='Cartas GNCOM'!P22 -> 0 | E6: ='Cartas GNCOM'!P21 -> 0 | F6: ='Cartas GNCOM'!P20 -> 17 | G6: ='Cartas GNCOM'!P19 -> 0
B7: Facturas GNCOMP | C7: ='Facturas GNCOMP'!P17 -> 11 | D7: ='Facturas GNCOMP'!P16 -> 0 | E7: ='Facturas GNCOMP'!P15 -> 0 | F7: ='Facturas GNCOMP'!P14 -> 11 | G7: ='Facturas GNCOMP'!P13 -> 0
B8: Cartas GNOMP | C8: ='Cartas GNOMP'!P8 -> 2 | D8: ='Cartas GNOMP'!P7 -> 0 | E8: ='Cartas GNOMP'!P6 -> 0 | F8: ='Cartas GNOMP'!P5 -> 2 | G8: ='Cartas GNOMP'!P4 -> 0
B9: Facturas CRGP | C9: ='Facturas CRGP'!R108 -> 102 | D9: ='Facturas CRGP'!R107 -> 0 | E9: ='Facturas CRGP'!R106 -> 0 | F9: ='Facturas CRGP'!R105 -> 102 | G9: ='Facturas CRGP'!R104 -> 0
B10: Cartas CRGP | C10: ='Cartas CRGP'!Q42 -> 36 | D10: ='Cartas CRGP'!Q41 -> 0 | E10: ='Cartas CRGP'!Q40 -> 0 | F10: ='Cartas CRGP'!Q39 -> 36 | G10: ='Cartas CRGP'!Q38 -> 0
B11: Contratos CRGP | C11: ='Contratos CRGP'!Q11 -> 5 | D11: ='Contratos CRGP'!Q10 -> 0 | E11: ='Contratos CRGP'!Q9 -> 0 | F11: ='Contratos CRGP'!Q8 -> 5 | G11: ='Contratos CRGP'!Q7 -> 0
B12: MEGA | C12: =MEGA!AL62 -> 49 | D12: =MEGA!AL61 -> 10 | E12: =MEGA!AL60 -> 5 | F12: =MEGA!AL59 -> 34 | G12: =MEGA!AL58 -> 0.20408163

Sheet Facturas SAP NI
A1: Sistema / Aplicación | B1: Modulo | C1: Proceso | D1: Subproceso | E1: Funcionalidad | F1: COD CdP | G1: Nombre CdP | H1: Resumen | I1: Precondiciones | J1: Tipo de Ejecución | K1: Criticidad | L1: Autor | M1: Datos del CdP | N1: Resultado esperado | O1: COMENTARIOS NEGOCIO | P1: Responsable | Q1: Fecha inicio | R1: Fecha Fin | S1: Fecha Liberado | T1: Resultado OK/KO
A2: SAP ISU | B2: Facturación | C2: Facturación ISU | D2: Facturación | E2: Impresión | F2: CP_001 | G2: =CONCATENATE(F2,"_",H2) -> CP_001_Impresión factura de ciclo (FE*), sector ELE, tarifa 2.0TD - ES | H2: Impresión factura de ciclo (FE*), sector ELE, tarifa 2.0TD - ES | J2: Manual | K2: Alta | L2: IBM | M2: Factura: | O2: Revisión OK | P2: Sergi Monte / Angel Jaime (M. Simón) | Q2: 46013 | R2: 45666
A3: SAP ISU | B3: Facturación | C3: Facturación ISU | D3: Facturación | E3: Impresión | F3: CP_002 | G3: =CONCATENATE(F3,"_",H3) -> CP_002_Impresión factura de ciclo (FE*), sector ELE, tarifa 2.0TD - CA | H3: Impresión factura de ciclo (FE*), sector ELE, tarifa 2.0TD - CA | J3: Manual | K3: Alta | L3: IBM | M3: Factura: | O3: Revisión OK | P3: Sergi Monte / Angel Jaime (M. Simón) | Q3: 46013 | R3: 45666 | T3: N/A
A4: SAP ISU | B4: Facturación | C4: Facturación ISU | D4: Facturación | E4: Impresión | F4: CP_003 | G4: =CONCATENATE(F4,"_",H4) -> CP_003_Impresión factura de ciclo (FE*), sector ELE, tarifa 2.0TD - EU | H4: Impresión factura de ciclo (FE*), sector ELE, tarifa 2.0TD - EU | J4: Manual | K4: Alta | L4: IBM | M4: Factura: | O4: Revisión OK | P4: Sergi Monte / Angel Jaime (M. Simón) | Q4: 46013 | R4: 45666 | T4: N/A
A5: SAP ISU | B5: Facturación | C5: Facturación ISU | D5: Facturación | E5: Impresión | F5: CP_004 | G5: =CONCATENATE(F5,"_",H5) -> CP_004_Impresión factura de ciclo (FE*), sector ELE, tarifa 2.0TD - GA | H5: Impresión factura de ciclo (FE*), sector ELE, tarifa 2.0TD - GA | J5: Manual | K5: Alta | L5: IBM | M5: Factura: | O5: Revisión OK | P5: Sergi Monte / Angel Jaime (M. Simón) | Q5: 46013 | R5: 45666 | T5: N/A
A6: SAP ISU | B6: Facturación | C6: Facturación ISU | D6: Facturación | E6: Impresión | F6: CP_005 | G6: =CONCATENATE(F6,"_",H6) -> CP_005_Impresión Refacturación (RE*), sector ELE, tarifa 2.0TD - ES | H6: Impresión Refacturación (RE*), sector ELE, tarifa 2.0TD - ES | J6: Manual | K6: Alta | L6: IBM | M6: Factura: | O6: Revisión OK | P6: Sergi Monte / Angel Jaime (M. Simón) | Q6: 46013 | R6: 45666
A7: SAP ISU | B7: Facturación | C7: Facturación ISU | D7: Facturación | E7: Impresión | F7: CP_006 | G7: =CONCATENATE(F7,"_",H7) -> CP_006_Impresión Refacturación (RE*), sector ELE, tarifa 2.0TD - CA | H7: Impresión Refacturación (RE*), sector ELE, tarifa 2.0TD - CA | J7: Manual | K7: Alta | L7: IBM | M7: Factura: | O7: Revisión OK | P7: Sergi Monte / Angel Jaime (M. Simón) | Q7: 46013 | R7: 45666 | T7: N/A
A8: SAP ISU | B8: Facturación | C8: Facturación ISU | D8: Facturación | E8: Impresión | F8: CP_007 | G8: =CONCATENATE(F8,"_",H8) -> CP_007_Impresión Refacturación (RE*), sector ELE, tarifa 2.0TD - EU | H8: Impresión Refacturación (RE*), sector ELE, tarifa 2.0TD - EU | J8: Manual | K8: Alta | L8: IBM | M8: Factura: | O8: Revisión OK | P8: Sergi Monte / Angel Jaime (M. Simón) | Q8: 46013 | R8: 45666 | T8: N/A
A9: SAP ISU | B9: Facturación | C9: Facturación ISU | D9: Facturación | E9: Impresión | F9: CP_008 | G9: =CONCATENATE(F9,"_",H9) -> CP_008_Impresión Refacturación (RE*), sector ELE, tarifa 2.0TD - GA | H9: Impresión Refacturación (RE*), sector ELE, tarifa 2.0TD - GA | J9: Manual | K9: Alta | L9: IBM | M9: Factura: | O9: Revisión OK | P9: Sergi Monte / Angel Jaime (M. Simón) | Q9: 46013 | R9: 45666 | T9: N/A
A10: SAP ISU | B10: Facturación | C10: Facturación ISU | D10: Facturación | E10: Impresión | F10: CP_009 | G10: =CONCATENATE(F10,"_",H10) -> CP_009_Impresión factura de anulación (SU*), sector ELE, tarifa 2.0TD -ES | H10: Impresión factura de anulación (SU*), sector ELE, tarifa 2.0TD -ES | J10: Manual | K10: Alta | L10: IBM | M10: Factura: | O10: Revisión OK | P10: Sergi Monte / Angel Jaime (M. Simón) | Q10: 46013 | R10: 45666
A11: SAP ISU | B11: Facturación | C11: Facturación ISU | D11: Facturación | E11: Impresión | F11: CP_010 | G11: =CONCATENATE(F11,"_",H11) -> CP_010_Impresión factura de anulación (SU*), sector ELE, tarifa 2.0TD -CA | H11: Impresión factura de anulación (SU*), sector ELE, tarifa 2.0TD -CA | J11: Manual | K11: Alta | L11: IBM | M11: Factura: | O11: Revisión OK | P11: Sergi Monte / Angel Jaime (M. Simón) | Q11: 46013 | R11: 45666 | T11: N/A
A12: SAP ISU | B12: Facturación | C12: Facturación ISU | D12: Facturación | E12: Impresión | F12: CP_011 | G12: =CONCATENATE(F12,"_",H12) -> CP_011_Impresión factura de anulación (SU*), sector ELE, tarifa 2.0TD -EU | H12: Impresión factura de anulación (SU*), sector ELE, tarifa 2.0TD -EU | J12: Manual | K12: Alta | L12: IBM | M12: Factura: | O12: Revisión OK | P12: Sergi Monte / Angel Jaime (M. Simón) | Q12: 46013 | R12: 45666 | T12: N/A
A13: SAP ISU | B13: Facturación | C13: Facturación ISU | D13: Facturación | E13: Impresión | F13: CP_012 | G13: =CONCATENATE(F13,"_",H13) -> CP_012_Impresión factura de anulación (SU*), sector ELE, tarifa 2.0TD -GA | H13: Impresión factura de anulación (SU*), sector ELE, tarifa 2.0TD -GA | J13: Manual | K13: Alta | L13: IBM | M13: Factura: | O13: Revisión OK | P13: Sergi Monte / Angel Jaime (M. Simón) | Q13: 46013 | R13: 45666 | T13: N/A
A14: SAP ISU | B14: Facturación | C14: Facturación ISU | D14: Facturación | E14: Impresión | F14: CP_013 | G14: =CONCATENATE(F14,"_",H14) -> CP_013_Impresión factura de Ajuste (AE*), sector ELE, tarifa 2.0TD -ES | H14: Impresión factura de Ajuste (AE*), sector ELE, tarifa 2.0TD -ES | J14: Manual | K14: Alta | L14: IBM | M14: Factura: | O14: Revisión OK | P14: Sergi Monte / Angel Jaime (M. Simón) | Q14: 46013 | R14: 45666
A15: SAP ISU | B15: Facturación | C15: Facturación ISU | D15: Facturación | E15: Impresión | F15: CP_014 | G15: =CONCATENATE(F15,"_",H15) -> CP_014_Impresión factura de Ajuste (AE*), sector ELE, tarifa 2.0TD -CA | H15: Impresión factura de Ajuste (AE*), sector ELE, tarifa 2.0TD -CA | J15: Manual | K15: Alta | L15: IBM | M15: Factura: | O15: Revisión OK | P15: Sergi Monte / Angel Jaime (M. Simón) | Q15: 46013 | R15: 45666 | T15: N/A
A16: SAP ISU | B16: Facturación | C16: Facturación ISU | D16: Facturación | E16: Impresión | F16: CP_015 | G16: =CONCATENATE(F16,"_",H16) -> CP_015_Impresión factura de Ajuste (AE*), sector ELE, tarifa 2.0TD -EU | H16: Impresión factura de Ajuste (AE*), sector ELE, tarifa 2.0TD -EU | J16: Manual | K16: Alta | L16: IBM | M16: Factura: | O16: Revisión OK | P16: Sergi Monte / Angel Jaime (M. Simón) | Q16: 46013 | R16: 45666 | T16: N/A
A17: SAP ISU | B17: Facturación | C17: Facturación ISU | D17: Facturación | E17: Impresión | F17: CP_016 | G17: =CONCATENATE(F17,"_",H17) -> CP_016_Impresión factura de Ajuste (AE*), sector ELE, tarifa 2.0TD -GA | H17: Impresión factura de Ajuste (AE*), sector ELE, tarifa 2.0TD -GA | J17: Manual | K17: Alta | L17: IBM | M17: Factura: | O17: Revisión OK | P17: Sergi Monte / Angel Jaime (M. Simón) | Q17: 46013 | R17: 45666 | T17: N/A
A18: SAP ISU | B18: Facturación | C18: Facturación ISU | D18: Facturación | E18: Impresión | F18: CP_017 | G18: =CONCATENATE(F18,"_",H18) -> CP_017_Impresión factura de ciclo (FE*), sector ELE, tarifa 3.0TD - ES | H18: Impresión factura de ciclo (FE*), sector ELE, tarifa 3.0TD - ES | J18: Manual | K18: Alta | L18: IBM | M18: Factura: | O18: Revisión OK | P18: Sergi Monte / Angel Jaime (M. Simón) | Q18: 46013 | R18: 45666
A19: SAP ISU | B19: Facturación | C19: Facturación ISU | D19: Facturación | E19: Impresión | F19: CP_018 | G19: =CONCATENATE(F19,"_",H19) -> CP_018_Impresión factura de ciclo (FE*), sector ELE, tarifa 3.0TD - CA | H19: Impresión factura de ciclo (FE*), sector ELE, tarifa 3.0TD - CA | J19: Manual | K19: Alta | L19: IBM | M19: Factura: | O19: Revisión OK | P19: Sergi Monte / Angel Jaime (M. Simón) | Q19: 46013 | R19: 45666 | T19: N/A
A20: SAP ISU | B20: Facturación | C20: Facturación ISU | D20: Facturación | E20: Impresión | F20: CP_019 | G20: =CONCATENATE(F20,"_",H20) -> CP_019_Impresión factura de ciclo (FE*), sector ELE, tarifa 3.0TD - EU | H20: Impresión factura de ciclo (FE*), sector ELE, tarifa 3.0TD - EU | J20: Manual | K20: Alta | L20: IBM | M20: Factura: | O20: Revisión OK | P20: Sergi Monte / Angel Jaime (M. Simón) | Q20: 46013 | R20: 45666 | T20: N/A
A21: SAP ISU | B21: Facturación | C21: Facturación ISU | D21: Facturación | E21: Impresión | F21: CP_020 | G21: =CONCATENATE(F21,"_",H21) -> CP_020_Impresión factura de ciclo (FE*), sector ELE, tarifa 3.0TD - GA | H21: Impresión factura de ciclo (FE*), sector ELE, tarifa 3.0TD - GA | J21: Manual | K21: Alta | L21: IBM | M21: Factura: | O21: Revisión OK | P21: Sergi Monte / Angel Jaime (M. Simón) | Q21: 46013 | R21: 45666 | T21: N/A
A22: SAP ISU | B22: Facturación | C22: Facturación ISU | D22: Facturación | E22: Impresión | F22: CP_021 | G22: =CONCATENATE(F22,"_",H22) -> CP_021_Impresión Refacturación (RE*), sector ELE, tarifa 3.0TD - ES | H22: Impresión Refacturación (RE*), sector ELE, tarifa 3.0TD - ES | J22: Manual | K22: Alta | L22: IBM | M22: Factura: | O22: Revisión OK | P22: Sergi Monte / Angel Jaime (M. Simón) | Q22: 46013 | R22: 45666
A23: SAP ISU | B23: Facturación | C23: Facturación ISU | D23: Facturación | E23: Impresión | F23: CP_022 | G23: =CONCATENATE(F23,"_",H23) -> CP_022_Impresión Refacturación (RE*), sector ELE, tarifa 3.0TD - CA | H23: Impresión Refacturación (RE*), sector ELE, tarifa 3.0TD - CA | J23: Manual | K23: Alta | L23: IBM | M23: Factura: | O23: Revisión OK | P23: Sergi Monte / Angel Jaime (M. Simón) | Q23: 46013 | R23: 45666 | T23: N/A
A24: SAP ISU | B24: Facturación | C24: Facturación ISU | D24: Facturación | E24: Impresión | F24: CP_023 | G24: =CONCATENATE(F24,"_",H24) -> CP_023_Impresión Refacturación (RE*), sector ELE, tarifa 3.0TD - EU | H24: Impresión Refacturación (RE*), sector ELE, tarifa 3.0TD - EU | J24: Manual | K24: Alta | L24: IBM | M24: Factura: | O24: Revisión OK | P24: Sergi Monte / Angel Jaime (M. Simón) | Q24: 46013 | R24: 45666 | T24: N/A
A25: SAP ISU | B25: Facturación | C25: Facturación ISU | D25: Facturación | E25: Impresión | F25: CP_024 | G25: =CONCATENATE(F25,"_",H25) -> CP_024_Impresión Refacturación (RE*), sector ELE, tarifa 3.0TD - GA | H25: Impresión Refacturación (RE*), sector ELE, tarifa 3.0TD - GA | J25: Manual | K25: Alta | L25: IBM | M25: Factura: | O25: Revisión OK | P25: Sergi Monte / Angel Jaime (M. Simón) | Q25: 46013 | R25: 45666 | T25: N/A
A26: SAP ISU | B26: Facturación | C26: Facturación ISU | D26: Facturación | E26: Impresión | F26: CP_025 | G26: =CONCATENATE(F26,"_",H26) -> CP_025_Impresión factura de anulación (SU*), sector ELE, tarifa 3.0TD - ES | H26: Impresión factura de anulación (SU*), sector ELE, tarifa 3.0TD - ES | J26: Manual | K26: Alta | L26: IBM | M26: Factura: | O26: Revisión OK | P26: Sergi Monte / Angel Jaime (M. Simón) | Q26: 46013 | R26: 45666
A27: SAP ISU | B27: Facturación | C27: Facturación ISU | D27: Facturación | E27: Impresión | F27: CP_026 | G27: =CONCATENATE(F27,"_",H27) -> CP_026_Impresión factura de anulación (SU*), sector ELE, tarifa 3.0TD - CA | H27: Impresión factura de anulación (SU*), sector ELE, tarifa 3.0TD - CA | J27: Manual | K27: Alta | L27: IBM | M27: Factura: | O27: Revisión OK | P27: Sergi Monte / Angel Jaime (M. Simón) | Q27: 46013 | R27: 45666 | T27: N/A
A28: SAP ISU | B28: Facturación | C28: Facturación ISU | D28: Facturación | E28: Impresión | F28: CP_027 | G28: =CONCATENATE(F28,"_",H28) -> CP_027_Impresión factura de anulación (SU*), sector ELE, tarifa 3.0TD - EU | H28: Impresión factura de anulación (SU*), sector ELE, tarifa 3.0TD - EU | J28: Manual | K28: Alta | L28: IBM | M28: Factura: | O28: Revisión OK | P28: Sergi Monte / Angel Jaime (M. Simón) | Q28: 46013 | R28: 45666 | T28: N/A
A29: SAP ISU | B29: Facturación | C29: Facturación ISU | D29: Facturación | E29: Impresión | F29: CP_028 | G29: =CONCATENATE(F29,"_",H29) -> CP_028_Impresión factura de anulación (SU*), sector ELE, tarifa 3.0TD - GA | H29: Impresión factura de anulación (SU*), sector ELE, tarifa 3.0TD - GA | J29: Manual | K29: Alta | L29: IBM | M29: Factura: | O29: Revisión OK | P29: Sergi Monte / Angel Jaime (M. Simón) | Q29: 46013 | R29: 45666 | T29: N/A
A30: SAP ISU | B30: Facturación | C30: Facturación ISU | D30: Facturación | E30: Impresión | F30: CP_029 | G30: =CONCATENATE(F30,"_",H30) -> CP_029_Impresión factura de ciclo (FE*), sector ELE, tarifa 6.0TD - ES | H30: Impresión factura de ciclo (FE*), sector ELE, tarifa 6.0TD - ES | J30: Manual | K30: Alta | L30: IBM | M30: Factura: | O30: Revisión OK | P30: Sergi Monte / Angel Jaime (M. Simón) | Q30: 46013 | R30: 45666
A31: SAP ISU | B31: Facturación | C31: Facturación ISU | D31: Facturación | E31: Impresión | F31: CP_030 | G31: =CONCATENATE(F31,"_",H31) -> CP_030_Impresión factura de ciclo (FE*), sector ELE, tarifa 6.0TD - CA | H31: Impresión factura de ciclo (FE*), sector ELE, tarifa 6.0TD - CA | J31: Manual | K31: Alta | L31: IBM | M31: Factura: | O31: Revisión OK | P31: Sergi Monte / Angel Jaime (M. Simón) | Q31: 46013 | R31: 45666 | T31: N/A
A32: SAP ISU | B32: Facturación | C32: Facturación ISU | D32: Facturación | E32: Impresión | F32: CP_031 | G32: =CONCATENATE(F32,"_",H32) -> CP_031_Impresión factura de ciclo (FE*), sector ELE, tarifa 6.0TD - EU | H32: Impresión factura de ciclo (FE*), sector ELE, tarifa 6.0TD - EU | J32: Manual | K32: Alta | L32: IBM | M32: Factura: | O32: Revisión OK | P32: Sergi Monte / Angel Jaime (M. Simón) | Q32: 46013 | R32: 45666 | T32: N/A
A33: SAP ISU | B33: Facturación | C33: Facturación ISU | D33: Facturación | E33: Impresión | F33: CP_032 | G33: =CONCATENATE(F33,"_",H33) -> CP_032_Impresión factura de ciclo (FE*), sector ELE, tarifa 6.0TD - GA | H33: Impresión factura de ciclo (FE*), sector ELE, tarifa 6.0TD - GA | J33: Manual | K33: Alta | L33: IBM | M33: Factura: | O33: Revisión OK | P33: Sergi Monte / Angel Jaime (M. Simón) | Q33: 46013 | R33: 45666 | T33: N/A
A34: SAP ISU | B34: Facturación | C34: Facturación ISU | D34: Facturación | E34: Impresión | F34: CP_033 | G34: =CONCATENATE(F34,"_",H34) -> CP_033_Impresión Refacturación (RE*), sector ELE, tarifa 6.xTD - ES | H34: Impresión Refacturación (RE*), sector ELE, tarifa 6.xTD - ES | J34: Manual | K34: Alta | L34: IBM | M34: Factura: | O34: Revisión OK | P34: Sergi Monte / Angel Jaime (M. Simón) | Q34: 46013 | R34: 45666
A35: SAP ISU | B35: Facturación | C35: Facturación ISU | D35: Facturación | E35: Impresión | F35: CP_034 | G35: =CONCATENATE(F35,"_",H35) -> CP_034_Impresión Refacturación (RE*), sector ELE, tarifa 6.xTD - CA | H35: Impresión Refacturación (RE*), sector ELE, tarifa 6.xTD - CA | J35: Manual | K35: Alta | L35: IBM | M35: Factura: | O35: Revisión OK | P35: Sergi Monte / Angel Jaime (M. Simón) | Q35: 46013 | R35: 45666 | T35: N/A
A36: SAP ISU | B36: Facturación | C36: Facturación ISU | D36: Facturación | E36: Impresión | F36: CP_035 | G36: =CONCATENATE(F36,"_",H36) -> CP_035_Impresión Refacturación (RE*), sector ELE, tarifa 6.xTD - EU | H36: Impresión Refacturación (RE*), sector ELE, tarifa 6.xTD - EU | J36: Manual | K36: Alta | L36: IBM | M36: Factura: | O36: Revisión OK | P36: Sergi Monte / Angel Jaime (M. Simón) | Q36: 46013 | R36: 45666 | T36: N/A
A37: SAP ISU | B37: Facturación | C37: Facturación ISU | D37: Facturación | E37: Impresión | F37: CP_036 | G37: =CONCATENATE(F37,"_",H37) -> CP_036_Impresión Refacturación (RE*), sector ELE, tarifa 6.xTD - GA | H37: Impresión Refacturación (RE*), sector ELE, tarifa 6.xTD - GA | J37: Manual | K37: Alta | L37: IBM | M37: Factura: | O37: Revisión OK | P37: Sergi Monte / Angel Jaime (M. Simón) | Q37: 46013 | R37: 45666 | T37: N/A
A38: SAP ISU | B38: Facturación | C38: Facturación ISU | D38: Facturación | E38: Impresión | F38: CP_037 | G38: =CONCATENATE(F38,"_",H38) -> CP_037_Impresión factura de anulación (SU*), sector ELE, tarifa 6.xTD - ES | H38: Impresión factura de anulación (SU*), sector ELE, tarifa 6.xTD - ES | J38: Manual | K38: Alta | L38: IBM | M38: Factura: | O38: Revisión OK | P38: Sergi Monte / Angel Jaime (M. Simón) | Q38: 46013 | R38: 45666
A39: SAP ISU | B39: Facturación | C39: Facturación ISU | D39: Facturación | E39: Impresión | F39: CP_038 | G39: =CONCATENATE(F39,"_",H39) -> CP_038_Impresión factura de anulación (SU*), sector ELE, tarifa 6.xTD - CA | H39: Impresión factura de anulación (SU*), sector ELE, tarifa 6.xTD - CA | J39: Manual | K39: Alta | L39: IBM | M39: Factura: | O39: Revisión OK | P39: Sergi Monte / Angel Jaime (M. Simón) | Q39: 46013 | R39: 45666 | T39: N/A
A40: SAP ISU | B40: Facturación | C40: Facturación ISU | D40: Facturación | E40: Impresión | F40: CP_039 | G40: =CONCATENATE(F40,"_",H40) -> CP_039_Impresión factura de anulación (SU*), sector ELE, tarifa 6.xTD - EU | H40: Impresión factura de anulación (SU*), sector ELE, tarifa 6.xTD - EU | J40: Manual | K40: Alta | L40: IBM | M40: Factura: | O40: Revisión OK | P40: Sergi Monte / Angel Jaime (M. Simón) | Q40: 46013 | R40: 45666 | T40: N/A
...

Sheet Facturas GNCOM
A1: Proyecto | B1: Tipo | C1: Estado | D1: Prioridad | E1: Codigo de Prueba | F1: Asunto | G1: Módulos Delta | H1: Datos de prueba | I1: Técnica de pruebas | J1: Resultado esperado | K1: COMENTARIOS NEGOCIO | L1: Responsable | M1: Fecha inicio | N1: Fecha Fin | O1: Fecha Liberado | P1: Resultado OK/KO | Q1: xml papyrus | R1: pdf papyrus
A2: Proyecto Compositor Documental - GNCOM | B2: Caso prueba | C2: Nueva | D2: Normal | E2: FAC_001 | F2: Factura Gas España F001-F031 Subformulario Gas España Lectura mensual | G2: FACTURACIÓN | H2: Factura Gas España con Lectura mensual Formulario: F001 Subformulario: F031 Idioma: CA, ES, EU, GA | I2: Impresión facturas en los distintos idiomas | J2: Generación de xml y PDF | K2: Revisión OK | L2: Javi Granadino / Esther Rigo (M. Simón) | M2: 46013 | N2: 45666 | O2: 46027 | Q2: FAC_001_GA_PI25142000355153.xml FAC_001_ES_PI25142000355153.xml FAC_001_CA_PI25142000355153.xml FAC_001_EU_PI25142000355153.xml | R2: FAC_001_GA_PI25142000355153.pdf FAC_001_ES_PI25142000355153.pdf FAC_001_CA_PI25142000355153.des.afp.pdf FAC_001_EU_PI25142000355153.des.afp.pdf
A3: Proyecto Compositor Documental - GNCOM | B3: Caso prueba | C3: Nueva | D3: Normal | E3: FAC_002 | F3: Factura Gas España F001-F011 Subformulario Gas España Lectura diaria con curva | G3: FACTURACIÓN | H3: Factura Gas España con Lectura diaria con curva Formulario: F001 Subformulario: F011 Idioma: CA, ES, EU, GA | I3: Impresión facturas en los distintos idiomas | J3: Generación de xml y PDF | K3: Revisión OK | L3: Javi Granadino / Esther Rigo (M. Simón) | M3: 46013 | N3: 45666 | O3: 46027 | Q3: FAC_002_ES_PI25142000387240.xml FAC_002_GA_PI25142000387240.xml FAC_002_EU_PI25142000387240.xml FAC_002_CA_PI25142000387240.xml | R3: FAC_002_ES_PI25142000387240.pdf FAC_002_GA_PI25142000387240.pdf FAC_002_EU_PI25142000387240.pdf FAC_002_CA_PI25142000387240.pdf
A4: Proyecto Compositor Documental - GNCOM | B4: Caso prueba | C4: Nueva | D4: Normal | E4: FAC_003 | F4: Factura Gas España F001-F061 Subformulario Gas España mixta | G4: FACTURACIÓN | H4: Factura Gas España con lectura mixta Formulario: F001 Subformulario: F061 Idioma: CA, ES, EU, GA | I4: Impresión facturas en los distintos idiomas | J4: Generación de xml y PDF | K4: Revisión OK | L4: Javi Granadino / Esther Rigo (M. Simón) | M4: 46013 | N4: 45666 | O4: 46027 | Q4: FAC_003_ES_PI25142000363098.xml FAC_003_EU_PI25142000363098.xml FAC_003_CA_PI25142000363098.xml FAC_003_GA_PI25142000363098.xml | R4: FAC_003_ES_PI25142000363098.pdf FAC_003_EU_PI25142000363098.pdf FAC_003_CA_PI25142000363098.pdf FAC_003_GA_PI25142000363098.pdf
A5: Proyecto Compositor Documental - GNCOM | B5: Caso prueba | C5: Nueva | D5: Normal | E5: FAC_004 | F5: Factura Gas España GFU (F001) | G5: FACTURACIÓN | H5: Factura Gas España GFU (Multipunto) Formulario: F001 Subformulario: F031/F011/F061 Idioma: CA, ES, EU, GA | I5: Impresión facturas en los distintos idiomas | J5: Generación de xml y PDF | K5: Revisión OK | L5: Javi Granadino / Esther Rigo (M. Simón) | M5: 46013 | N5: 45666 | O5: 46027 | Q5: FAC_004_GA_PI25142000389656.xml FAC_004_CA_PI25142000389656.xml FAC_004_ES_PI25142000389656.xml FAC_004_EU_PI25142000389656.xml | R5: FAC_004_GA_PI25142000389656.pdf FAC_004_CA_PI25142000389656.afp.pdf FAC_004_ES_PI25142000389656.afp.pdf FAC_004_EU_PI25142000389656.afp.pdf
A6: Proyecto Compositor Documental - GNCOM | B6: Caso prueba | C6: Nueva | D6: Normal | E6: FAC_005 | F6: Factura Gas España Agrupación diaria (F001) | G6: FACTURACIÓN | H6: Factura Gas España Agrupación diaria Formulario: F001 Subformulario: F011 Idioma: CA, ES, EU, GA | I6: Impresión facturas en los distintos idiomas | J6: Generación de xml y PDF | K6: Revisión OK | L6: Javi Granadino / Esther Rigo (M. Simón) | M6: 46013 | N6: 45666 | O6: 46027 | Q6: FAC_005_ES_PI25142000386327.xml FAC_005_CA_PI25142000386327.xml FAC_005_EU_PI25142000386327.xml FAC_005_GA_PI25142000386327.xml | R6: FAC_005_ES_PI25142000386327.pdf FAC_005_CA_PI25142000386327.pdf FAC_005_EU_PI25142000386327.pdf FAC_005_GA_PI25142000386327.pdf
A7: Proyecto Compositor Documental - GNCOM | B7: Caso prueba | C7: Nueva | D7: Normal | E7: FAC_006 | F7: Factura Gas España CV (F001) | G7: FACTURACIÓN | H7: Factura Gas España CV (Cargo Vario) Formulario: F001 Subformulario: N/A Idioma: CA, ES, EU, GA | I7: Impresión facturas en los distintos idiomas | J7: Generación de xml y PDF | K7: Revisión OK | L7: Javi Granadino / Esther Rigo (M. Simón) | M7: 46013 | N7: 45666 | O7: 46027 | Q7: FAC_006_ES_PO24142000002567.xml FAC_006_CA_PO24142000002567.xml FAC_006_GA_PO24142000002567.xml FAC_006_EU_PO24142000002567.xml | R7: FAC_006_ES_PO24142000002567.afp.pdf FAC_006_CA_PO24142000002567.afp.pdf FAC_006_GA_PO24142000002567.afp.pdf FAC_006_EU_PO24142000002567.afp.pdf
A8: Proyecto Compositor Documental - GNCOM | B8: Caso prueba | C8: Nueva | D8: Normal | E8: FAC_007 | F8: Factura de ajuste Gas España (F001) | G8: FACTURACIÓN | H8: Factura de ajuste Gas España Formulario: F001 Subformulario: F011/F031/F061 Idioma: CA, ES, EU, GA | I8: Impresión facturas en los distintos idiomas | J8: Generación de xml y PDF | K8: Revisión OK | L8: Javi Granadino / Esther Rigo (M. Simón) | M8: 46013 | N8: 45666 | Q8: | PA25142000045897 | DazelMessage_378632.xml | DazelMessage_378632_F001.afp.pdf | F001 | F031 | CatalÃ¡n | | PA25142000045897 | DazelMessage_378628.xml | DazelMessage_378628.afp.pdf | F001 | F031 | EspaÃ±ol | | PA25142000045897 | DazelMessage_378678.xml | DazelMessage_378678_F001.afp.pdf | F001 | F031 | Euskera | | PA25142000045897 | DazelMessage_378647.xml | DazelMessage_378647_F001.afp.pdf | F001 | F031 | Gallego | | R8: | PA25142000045897 | DazelMessage_378632.xml | DazelMessage_378632_F001.afp.pdf | F001 | F031 | CatalÃ¡n | | PA25142000045897 | DazelMessage_378628.xml | DazelMessage_378628.afp.pdf | F001 | F031 | EspaÃ±ol | | PA25142000045897 | DazelMessage_378678.xml | DazelMessage_378678_F001.afp.pdf | F001 | F031 | Euskera | | PA25142000045897 | DazelMessage_378647.xml | DazelMessage_378647_F001.afp.pdf | F001 | F031 | Gallego |
A9: Proyecto Compositor Documental - GNCOM | B9: Caso prueba | C9: Nueva | D9: Normal | E9: FAC_008 | F9: Factura de recálculo Gas España (F001) | G9: FACTURACIÓN | H9: Factura de recálculo Gas España Formulario: F001 Subformulario: F011/F031/F061 Idioma: CA, ES, EU, GA | I9: Impresión facturas en los distintos idiomas | J9: Generación de xml y PDF | K9: Revisión OK | L9: Javi Granadino / Esther Rigo (M. Simón) | M9: 46013 | N9: 45666 | Q9: | PR25142000004972 | DazelMessage_378633.xml | DazelMessage_378633_F001.afp.pdf | F001 | F011 | CatalÃ¡n | | PR25142000004972 | DazelMessage_378627.xml | DazelMessage_378627.afp.pdf | F001 | F011 | EspaÃ±ol | | PR25142000004972 | DazelMessage_378677.xml | DazelMessage_378677_F001.afp.pdf | F001 | F011 | Euskera | | PR25142000004972 | DazelMessage_378640.xml | DazelMessage_378640_F001.afp.pdf | F001 | F011 | Gallego | | R9: | PR25142000004972 | DazelMessage_378633.xml | DazelMessage_378633_F001.afp.pdf | F001 | F011 | CatalÃ¡n | | PR25142000004972 | DazelMessage_378627.xml | DazelMessage_378627.afp.pdf | F001 | F011 | EspaÃ±ol | | PR25142000004972 | DazelMessage_378677.xml | DazelMessage_378677_F001.afp.pdf | F001 | F011 | Euskera | | PR25142000004972 | DazelMessage_378640.xml | DazelMessage_378640_F001.afp.pdf | F001 | F011 | Gallego |
A10: Proyecto Compositor Documental - GNCOM | B10: Caso prueba | C10: Nueva | D10: Normal | E10: FAC_009 | F10: Factura de anulación Gas España (F001) | G10: FACTURACIÓN | H10: Factura de anulación Gas España Formulario: F001 Subformulario: F011/F031/F061 Idioma: CA, ES, EU, GA | I10: Impresión facturas en los distintos idiomas | J10: Generación de xml y PDF | K10: Revisión OK | L10: Javi Granadino / Esther Rigo (M. Simón) | M10: 46013 | N10: 45666 | Q10: | PS25142000009265 | DazelMessage_378632.xml | DazelMessage_378632_F001.afp.pdf | F001 | | CatalÃ¡n | | PS25142000009265 | DazelMessage_378628.xml | DazelMessage_378628.afp.pdf | F001 | | EspaÃ±ol | | PS25142000009265 | DazelMessage_378678.xml | DazelMessage_378678_F001.afp.pdf | F001 | | Euskera | | PS25142000009265 | DazelMessage_378647.xml | DazelMessage_378647_F001.afp.pdf | F001 | | Gallego | | R10: | PS25142000009265 | DazelMessage_378632.xml | DazelMessage_378632_F001.afp.pdf | F001 | | CatalÃ¡n | | PS25142000009265 | DazelMessage_378628.xml | DazelMessage_378628.afp.pdf | F001 | | EspaÃ±ol | | PS25142000009265 | DazelMessage_378678.xml | DazelMessage_378678_F001.afp.pdf | F001 | | Euskera | | PS25142000009265 | DazelMessage_378647.xml | DazelMessage_378647_F001.afp.pdf | F001 | | Gallego |
A11: Proyecto Compositor Documental - GNCOM | B11: Caso prueba | C11: Nueva | D11: Normal | E11: FAC_010 | F11: Factura de ajuste Gas España GFU (F001) | G11: FACTURACIÓN | H11: Factura de ajuste Gas España GFU (Multipunto) Formulario: F001 Subformulario: F011/F031/F061 Idioma: CA, ES, EU, GA | I11: Impresión facturas en los distintos idiomas | J11: Generación de xml y PDF | K11: Revisión OK | L11: Javi Granadino / Esther Rigo (M. Simón) | M11: 46013 | N11: 45666 | Q11: | PA25142000044574 | DazelMessage_378633.xml | DazelMessage_378633_F001.afp.pdf | F001 | F031 | CatalÃ¡n | | PA25142000044574 | DazelMessage_378627.xml | DazelMessage_378627.afp.pdf | F001 | F031 | EspaÃ±ol | | PA25142000044574 | DazelMessage_378677.xml | DazelMessage_378677_F001.afp.pdf | F001 | F031 | Euskera | | PA25142000044574 | DazelMessage_378640.xml | DazelMessage_378640_F001.afp.pdf | F001 | F031 | Gallego | | R11: | PA25142000044574 | DazelMessage_378633.xml | DazelMessage_378633_F001.afp.pdf | F001 | F031 | CatalÃ¡n | | PA25142000044574 | DazelMessage_378627.xml | DazelMessage_378627.afp.pdf | F001 | F031 | EspaÃ±ol | | PA25142000044574 | DazelMessage_378677.xml | DazelMessage_378677_F001.afp.pdf | F001 | F031 | Euskera | | PA25142000044574 | DazelMessage_378640.xml | DazelMessage_378640_F001.afp.pdf | F001 | F031 | Gallego |
A12: Proyecto Compositor Documental - GNCOM | B12: Caso prueba | C12: Nueva | D12: Normal | E12: FAC_011 | F12: Factura de recálculo Gas España GFU (F001) | G12: FACTURACIÓN | H12: Factura de recálculo Gas España GFU (Multipunto) Formulario: F001 Subformulario: F011/F031/F061 Idioma: CA, ES, EU, GA | I12: Impresión facturas en los distintos idiomas | J12: Generación de xml y PDF | K12: Revisión OK | L12: Javi Granadino / Esther Rigo (M. Simón) | M12: 46013 | N12: 45666 | Q12: | PR25142000004874 | DazelMessage_378633.xml | DazelMessage_378633_F001.afp.pdf | F001 | F031 | CatalÃ¡n | | PR25142000004874 | DazelMessage_378627.xml | DazelMessage_378627.afp.pdf | F001 | F031 | EspaÃ±ol | | PR25142000004874 | DazelMessage_378677.xml | DazelMessage_378677_F001.afp.pdf | F001 | F031 | Euskera | | PR25142000004874 | DazelMessage_378640.xml | DazelMessage_378640_F001.afp.pdf | F001 | F031 | Gallego | | R12: | PR25142000004874 | DazelMessage_378633.xml | DazelMessage_378633_F001.afp.pdf | F001 | F031 | CatalÃ¡n | | PR25142000004874 | DazelMessage_378627.xml | DazelMessage_378627.afp.pdf | F001 | F031 | EspaÃ±ol | | PR25142000004874 | DazelMessage_378677.xml | DazelMessage_378677_F001.afp.pdf | F001 | F031 | Euskera | | PR25142000004874 | DazelMessage_378640.xml | DazelMessage_378640_F001.afp.pdf | F001 | F031 | Gallego |
A13: Proyecto Compositor Documental - GNCOM | B13: Caso prueba | C13: Nueva | D13: Normal | E13: FAC_012 | F13: Factura de anulación Gas España GFU (F001) | G13: FACTURACIÓN | H13: Factura de anulación Gas España GFU (Multipunto) Formulario: F001 Subformulario: F011/F031/F061 Idioma: CA, ES, EU, GA | I13: Impresión facturas en los distintos idiomas | J13: Generación de xml y PDF | K13: Revisión OK | L13: Javi Granadino / Esther Rigo (M. Simón) | M13: 46013 | N13: 45666 | Q13: | PS25142000008202 | DazelMessage_378633.xml | DazelMessage_378633_F001.afp.pdf | F001 | | CatalÃ¡n | | PS25142000008202 | DazelMessage_378627.xml | DazelMessage_378627.afp.pdf | F001 | | EspaÃ±ol | | PS25142000008202 | DazelMessage_378677.xml | DazelMessage_378677_F001.afp.pdf | F001 | | Euskera | | PS25142000008202 | DazelMessage_378640.xml | DazelMessage_378640_F001.afp.pdf | F001 | | Gallego | | R13: | PS25142000008202 | DazelMessage_378633.xml | DazelMessage_378633_F001.afp.pdf | F001 | | CatalÃ¡n | | PS25142000008202 | DazelMessage_378627.xml | DazelMessage_378627.afp.pdf | F001 | | EspaÃ±ol | | PS25142000008202 | DazelMessage_378677.xml | DazelMessage_378677_F001.afp.pdf | F001 | | Euskera | | PS25142000008202 | DazelMessage_378640.xml | DazelMessage_378640_F001.afp.pdf | F001 | | Gallego |
A14: Proyecto Compositor Documental - GNCOM | B14: Caso prueba | C14: Nueva | D14: Normal | E14: FAC_013 | F14: Factura Electricidad España F002-F012 Subformulario Electricidad España 1 y 3 periodos | G14: FACTURACIÓN | H14: Factura Electricidad España con 1 o 3 periodos Formulario: F002 Subformulario: F012 Idioma: CA, ES, EU, GA | I14: Impresión facturas en los distintos idiomas | J14: Generación de xml y PDF | K14: Revisión OK | L14: Javi Granadino / Esther Rigo (M. Simón) | M14: 46013 | N14: 45666 | Q14: FAC_013_ES_PI25142000386163.xml FAC_013_CA_PI25142000386163.xml FAC_013_EU_PI25142000386163.xml FAC_013_GA_PI25142000386163.xml | R14: FAC_013_ES_PI25142000386163.afp.pdf FAC_013_CA_PI25142000386163.pdf FAC_013_EU_PI25142000386163.pdf FAC_013_GA_PI25142000386163.pdf
A15: Proyecto Compositor Documental - GNCOM | B15: Caso prueba | C15: Nueva | D15: Normal | E15: FAC_014 | F15: Factura Electricidad España F002-F022 Subformulario Electricidad España 6 periodos | G15: FACTURACIÓN | H15: Factura Electricidad España con 6 periodos Formulario: F002 Subformulario: F022 Idioma: CA, ES, EU, GA | I15: Impresión facturas en los distintos idiomas | J15: Generación de xml y PDF | K15: Revisión OK | L15: Javi Granadino / Esther Rigo (M. Simón) | M15: 46013 | N15: 45666 | Q15: FAC_014_ES_PI25142000387226.xml FAC_014_CA_PI25142000387226.xml FAC_014_EU_PI25142000387226.xml FAC_014_GA_PI25142000387226.xml | R15: FAC_014_ES_PI25142000387226.afp.pdf FAC_014_CA_PI25142000387226.afp.pdf FAC_014_EU_PI25142000387226.afp.pdf FAC_014_GA_PI25142000387226.afp.pdf
A16: Proyecto Compositor Documental - GNCOM | B16: Caso prueba | C16: Nueva | D16: Normal | E16: FAC_015 | F16: Factura Electricidad España GFU (F002) | G16: FACTURACIÓN | H16: Factura Electricidad España GFU (Multipunto) Formulario: F002 Subformulario: F012/F022 Idioma: CA, ES, EU, GA | I16: Impresión facturas en los distintos idiomas | J16: Generación de xml y PDF | K16: Revisión OK | L16: Javi Granadino / Esther Rigo (M. Simón) | M16: 46013 | N16: 45666 | Q16: FAC_015_GA_PI25142000343027.xml FAC_015_ES_PI25142000343027.xml FAC_015_CA_PI25142000343027.xml FAC_015_EU_PI25142000343027.xml | R16: FAC_015_GA_PI25142000343027.afp.pdf FAC_015_CA_PI25142000343027.afp.pdf FAC_015_ES_PI25142000343027.afp.pdf FAC_015_EU_PI25142000343027.afp.pdf
A17: Proyecto Compositor Documental - GNCOM | B17: Caso prueba | C17: Nueva | D17: Normal | E17: FAC_016 | F17: Factura Electricidad España CV (F002) | G17: FACTURACIÓN | H17: Factura Electricidad España CV (Cargo Vario) Formulario: F002 Subformulario: N/A Idioma: CA, ES, EU, GA | I17: Impresión facturas en los distintos idiomas | J17: Generación de xml y PDF | K17: Revisión OK | L17: Javi Granadino / Esther Rigo (M. Simón) | M17: 46013 | N17: 45666 | Q17: FAC_016_ES_PO24142000002805.xml FAC_016_CA_PO24142000002805.xml FAC_016_GA_PO24142000002805.xml FAC_016_EU_PO24142000002805.xml | R17: FAC_016_ES_PO24142000002805.afp.pdf FAC_016_CA_PO24142000002805.afp.pdf FAC_016_GA_PO24142000002805.afp.pdf FAC_016_EU_PO24142000002805.afp.pdf
A18: Proyecto Compositor Documental - GNCOM | B18: Caso prueba | C18: Nueva | D18: Normal | E18: FAC_017 | F18: Factura de ajuste Electricidad España (F002) | G18: FACTURACIÓN | H18: Factura de ajuste Electricidad España Formulario: F002 Subformulario: F012/F022 Idioma: CA, ES, EU, GA | I18: Impresión facturas en los distintos idiomas | J18: Generación de xml y PDF | K18: Revisión OK | L18: Javi Granadino / Esther Rigo (M. Simón) | M18: 46013 | N18: 45666 | Q18: FAC_017_ES_PA25142000032972.xml FAC_017_CA_PA25142000032972.xml FAC_017_EU_PA25142000032972.xml FAC_017_GA_PA25142000032972.xml | R18: FAC_017_ES_PA25142000032972.pdf FAC_017_CA_PA25142000032972.afp.pdf FAC_017_EU_PA25142000032972.afp.pdf FAC_017_GA_PA25142000032972.afp.pdf
A19: Proyecto Compositor Documental - GNCOM | B19: Caso prueba | C19: Nueva | D19: Normal | E19: FAC_018 | F19: Factura de recálculo Electricidad España (F002) | G19: FACTURACIÓN | H19: Factura de recálculo Electricidad España Formulario: F002 Subformulario: F012/F022 Idioma: CA, ES, EU, GA | I19: Impresión facturas en los distintos idiomas | J19: Generación de xml y PDF | K19: Revisión OK | L19: Javi Granadino / Esther Rigo (M. Simón) | M19: 46013 | N19: 45666 | Q19: | PR25142000004750 | DazelMessage_378650_Cat.xml | DazelMessage_378650_Cat_F002.afp.pdf | F002 | F022 | CatalÃ¡n | | PR25142000004750 | DazelMessage_378649_Cas.xml | DazelMessage_378649_Cas_F002.afp.pdf | F002 | F022 | EspaÃ±ol | | PR25142000004750 | DazelMessage_378680.xml | DazelMessage_378680_F002.afp.pdf | F002 | F022 | Euskera | | PR25142000004750 | DazelMessage_378639.xml | DazelMessage_378639_F002.afp.pdf | F002 | F022 | Gallego | | R19: | PR25142000004750 | DazelMessage_378650_Cat.xml | DazelMessage_378650_Cat_F002.afp.pdf | F002 | F022 | CatalÃ¡n | | PR25142000004750 | DazelMessage_378649_Cas.xml | DazelMessage_378649_Cas_F002.afp.pdf | F002 | F022 | EspaÃ±ol | | PR25142000004750 | DazelMessage_378680.xml | DazelMessage_378680_F002.afp.pdf | F002 | F022 | Euskera | | PR25142000004750 | DazelMessage_378639.xml | DazelMessage_378639_F002.afp.pdf | F002 | F022 | Gallego |
... A35: Proyecto Compositor Documental - GNCOM | B35: Caso prueba | C35: Nueva | D35: Normal | E35: FAC_034 | F35: Impresión agrupadores OOEE Eletricidad España Listado facturas y facturas | G35: FACTURACIÓN | H35: Carta de agrupador de Electricidad España con lista de facturas y facturas Carta: OOEE Con facturas: Formulario: F002 Subformulario: F012/F022 Idioma: CA, ES, EU, GA | I35: Impresión facturas en los distintos idiomas | J35: Generación de xml y PDF | K35: Revisión OK | L35: Javi Granadino / Esther Rigo (M. Simón) | M35: 46013 | N35: 45666 | Q35: DazelMessage_378684_OOEE_E_LLISTA+FACT.xml | R35: DazelMessage_378684_OOEE_E_LLISTA+FACT.afp.pdf
A36: Proyecto Compositor Documental - GNCOM | B36: Caso prueba | C36: Nueva | D36: Normal | E36: FAC_035 | F36: Factura Gas España F001-F011 Subformulario Gas España Lectura diaria con curva con más de 5 UMs | G36: FACTURACIÓN | H36: Factura Gas España con Lectura diaria con curva y más de 5 UMs Formulario: F001 Subformulario: F011 Idioma: CA, ES, EU, GA | I36: Impresión facturas en los distintos idiomas | J36: Generación de xml y PDF | L36: Javi Granadino / Esther Rigo (M. Simón) | M36: 46013 | N36: 45666 | O36: 46027 | Q36: FAC_035_CA_PI25142000322521.xml FAC_035_ES_PI25142000322521.xml FAC_035_EU_PI25142000322521.xml FAC_035_GA_PI25142000322521.xml | R36: FAC_035_CA_PI25142000322521.pdf FAC_035_ES_PI25142000322521.pdf FAC_035_EU_PI25142000322521.pdf FAC_035_GA_PI25142000322521.pdf
A37: Proyecto Compositor Documental - GNCOM | B37: Caso prueba | C37: Nueva | D37: Normal | E37: FAC_036 | F37: Factura Gas España GFU (F001) Diario y mensual | G37: FACTURACIÓN | H37: Factura Gas España GFU (Multipunto) Formulario: F001 Subformulario: F031/F011/F061 Idioma: ES | I37: Impresión facturas en los distintos idiomas | J37: Generación de xml y PDF | L37: Javi Granadino / Esther Rigo (M. Simón) | M37: 46013 | N37: 45666 | O37: 46027 | Q37: FAC_036_ES_PI25142000325752.xml | R37: FAC_036_ES_PI25142000325752.afp.pdf
C38: Nueva | D38: Normal | E38: FAC_037 | F38: Factura Electriciad España (F002) Excesos de potencia | G38: FACTURACIÓN | H38: Factura Electricidad España Formulario: F002 Subformulario: F022 Idioma: ES | I38: Impresión facturas en los distintos idiomas | J38: Generación de xml y PDF | L38: Javi Granadino / Esther Rigo (M. Simón) | M38: 46013 | N38: 45666 | Q38: FAC_037_ES_PI25142000348578.pdf | R38: FAC_037_ES_PI25142000348578.xml
P39: =(COUNTIF(P2:P35,"OK")/(COUNTBLANK(P2:P35)+(COUNTA(P2:P35)-(COUNTIF(P2:P35,"N/A"))))) -> 0 | Q39: Porcentaje de Avance
P40: =COUNTBLANK(P2:P38)+(COUNTA(P2:P38)-(COUNTIF(P2:P38,"N/A"))-(COUNTIF(P2:P38,"OK"))-(COUNTIF(P2:P38,"KO"))) -> 37 | Q40: Pendiente
P41: =COUNTIF(P2:P35,"KO") -> 0 | Q41: KO
P42: =COUNTIF(P2:P35,"OK") -> 0 | Q42: OK
P43: =COUNTBLANK(P2:P38)+(COUNTA(P2:P38)-(COUNTIF(P2:P38,"N/A"))) -> 37 | Q43: Total

Sheet Cartas GNCOM
A1: Proyecto | B1: Tipo | C1: Estado | D1: Prioridad | E1: Codigo de Prueba | F1: Asunto | G1: Módulos Delta | H1: Datos de prueba | I1: Técnica de pruebas | J1: Resultado esperado | K1: COMENTARIOS NEGOCIO | L1: Responsable | M1: Fecha inicio | N1: Fecha Fin | O1: Fecha Liberado | P1: Resultado OK/KO | Q1: xml papyrus | R1: pdf papyrus
A2: Proyecto Compositor Documental - GNCOM | B2: Caso prueba | C2: Nueva | D2: Normal | E2: COB_001 | F2: Generar carta C001__Carta 347 Totales | G2: Cobros | H2: Carta anterior de la tipología C001 Idioma: CA, ES, EU, GA | I2: Se marcan los eventos para reprocesar. Se ejecutan los procesos de procesamiento de eventos. Se ejecuta el proceso de generación de xml. | J2: Se genera el xml. | K2: Revisión OK | L2: Conchi Martinez | M2: 45662 | N2: 45666 | Q2: COB_001_Generar carta C001__Carta 347 Totales_Castellano_DazelMessage_376949 COB_001_C001_Carta 347 Totales_Catalan_DazelMessage_377025 COB_001_C001_Carta 347 Totales_Euskera_DazelMessage_377043 COB_001_C001_Carta 347 Totales_Gallego_DazelMessage_377044 | R2: COB_001_Generar carta C001__Carta 347 Totales_Castellano COB_001_C001_Carta_347_Totales_Catalan_DazelMessage_377025.afp COB_001_C001_Carta 347 Totales_Euskera_DazelMessage_377043 COB_001_C001_Carta 347 Totales_Gallego_DazelMessage_377044
A3: Proyecto Compositor Documental - GNCOM | B3: Caso prueba | C3: Nueva | D3: Normal | E3: COB_002 | F3: Generar carta C002__Carta 347 Detalle | G3: Cobros | H3: Carta anterior de la tipología C002 Idioma: CA, ES, EU, GA | I3: Se marcan los eventos para reprocesar. Se ejecutan los procesos de procesamiento de eventos. Se ejecuta el proceso de generación de xml. | J3: Se genera el xml. | K3: Revisión OK | L3: Conchi Martinez | M3: 45662 | N3: 45666 | Q3: COB_002_C002_Castellano_DazelMessage_376246 COB_002_C002_Catalan_DazelMessage_377045 COB_002_C002_Euskera_DazelMessage_377046 COB_002_C002_Gallego_DazelMessage_377047 | R3: COB_002_C002_Castellano_DazelMessage_376246.afp COB_002_C002_Catalan_DazelMessage_377045.afp COB_002_C002_Euskera_DazelMessage_377046.afp COB_002_C002_Gallego_DazelMessage_377047.afp
A4: Proyecto Compositor Documental - GNCOM | B4: Caso prueba | C4: Nueva | D4: Normal | E4: COB_003 | F4: Generar carta C003_1__Carta auditor deuda 0 | G4: Cobros | H4: Carta anterior de la tipología C003_1 Idioma: CA, ES, EU, GA | I4: Se marcan los eventos para reprocesar. Se ejecutan los procesos de procesamiento de eventos. Se ejecuta el proceso de generación de xml. | J4: Se genera el xml. | K4: Revisión OK | L4: Conchi Martinez | M4: 45662 | N4: 45666 | Q4: COB_003_C003_1__Carta auditor deuda 0_Castellano_DazelMessage_377131 COB_003_C003_1__Carta auditor deuda 0_Catalan COB_003_C003_1__Carta auditor deuda 0_Euskera COB_003_C003_1__Carta auditor deuda 0_Gallego | R4: COB_003_C003_1__Carta_auditor_deuda_0_Castellano_DazelMessage_377131.afp COB_003_C003_1__Carta_auditor_deuda_0_Catalan_DazelMessage_377131.afp COB_003_C003_1__Carta_auditor_deuda_0_Euskera_DazelMessage_377131.afp COB_003_C003_1__Carta_auditor_deuda_0_Gallego_DazelMessage_377131.afp
A5: Proyecto Compositor Documental - GNCOM | B5: Caso prueba | C5: Nueva | D5: Normal | E5: COB_004 | F5: Generar carta C003__Carta de auditoría | G5: Cobros | H5: Carta anterior de la tipología C003 Idioma: CA, ES, EU, GA | I5: Se marcan los eventos para reprocesar. Se ejecutan los procesos de procesamiento de eventos. Se ejecuta el proceso de generación de xml. | J5: Se genera el xml. | K5: Revisión OK | L5: Conchi Martinez | M5: 45662 | N5: 45666 | Q5: COB_004_C003_Carta de auditoría_castellano_DazelMessage_376915 COB_004_C003_Carta de auditoría_Catalan_DazelMessage_377048 COB_004_C003_Carta de auditoría_Euskera_DazelMessage_377049 COB_004_C003_Carta de auditoría_Gallego_DazelMessage_377050 | R5: COB_004_C003_Carta de auditoría_castellano_DazelMessage_376915.afp COB_004_C003_Carta_de_auditorÝa_Catalan_DazelMessage_377048.afp COB_004_C003_Carta_de_auditorÝa_Euskera_DazelMessage_377049.afp COB_004_C003_Carta_de_auditorÝa_Gallego_DazelMessage_377050.afp
A6: Proyecto Compositor Documental - GNCOM | B6: Caso prueba | C6: Nueva | D6: Normal | E6: COB_005 | F6: Generar carta C004__AAPP Modelo 1 | G6: Cobros | H6: Carta anterior de la tipología C004 Idioma: CA, ES, EU, GA | I6: Se marcan los eventos para reprocesar. Se ejecutan los procesos de procesamiento de eventos. Se ejecuta el proceso de generación de xml. | J6: Se genera el xml. | K6: Revisión OK | L6: Joaquin Pozo | M6: 45662 | N6: 45666
A7: Proyecto Compositor Documental - GNCOM | B7: Caso prueba | C7: Nueva | D7: Normal | E7: COB_006 | F7: Generar carta C005__AAPP Modelo 2 | G7: Cobros | H7: Carta anterior de la tipología C005 Idioma: CA, ES, EU, GA | I7: Se marcan los eventos para reprocesar. Se ejecutan los procesos de procesamiento de eventos. Se ejecuta el proceso de generación de xml. | J7: Se genera el xml. | K7: Revisión OK | L7: Joaquin Pozo | M7: 45662 | N7: 45666
A8: Proyecto Compositor Documental - GNCOM | B8: Caso prueba | C8: Nueva | D8: Normal | E8: COB_007 | F8: Generar carta C009__Carta Aviso Impago Domiciliado | G8: Cobros | H8: Carta anterior de la tipología C009 Idioma: CA, ES, EU, GA | I8: Se marcan los eventos para reprocesar. Se ejecutan los procesos de procesamiento de eventos. Se ejecuta el proceso de generación de xml. | J8: Se genera el xml. | K8: Revisión OK | L8: Joaquin Pozo | M8: 45662 | N8: 45666 | Q8: COB_007_C009_castellano COB_007_C009_catalan COB_007_C009_euskera COB_007_C009_gallego | R8: COB_007_C009_castellano COB_007_C009_catalan.afp COB_007_C009_euskera.afp COB_007_C009_gallego.afp
A9: Proyecto Compositor Documental - GNCOM | B9: Caso prueba | C9: Nueva | D9: Normal | E9: COB_008 | F9: Generar carta C010__Carta aviso impago no domiciliado | G9: Cobros | H9: Carta anterior de la tipología C010 Idioma: CA, ES, EU, GA | I9: Se marcan los eventos para reprocesar. Se ejecutan los procesos de procesamiento de eventos. Se ejecuta el proceso de generación de xml. | J9: Se genera el xml. | K9: Revisión OK | L9: Joaquin Pozo | M9: 45662 | N9: 45666 | Q9: COB_008_carta C010_castellano_DazelMessage_376311 COB_008_carta C010_catalan_DazelMessage_377300 COB_008_carta C010_Euskera_DazelMessage_377301 COB_008_carta C010_Gallego_DazelMessage_377312 | R9: COB_008_carta C010_castellano COB_008_carta C010_Euskera_DazelMessage_377301.afp COB_008_carta C010_Gallego_DazelMessage_377312.afp COB_008_carta C010_catalan_DazelMessage_377300.afp
A10: Proyecto Compositor Documental - GNCOM | B10: Caso prueba | C10: Nueva | D10: Normal | E10: COB_009 | F10: Generar carta C011__Carta Aviso Corte Gas | G10: Cobros | H10: Carta anterior de la tipología C011 Idioma: CA, ES, EU, GA | I10: Se marcan los eventos para reprocesar. Se ejecutan los procesos de procesamiento de eventos. Se ejecuta el proceso de generación de xml. | J10: Se genera el xml. | K10: Revisión OK | L10: Joaquin Pozo | M10: 45662 | N10: 45666 | Q10: COB_009_carta C011_castellano COB_009_carta C011_catalan_DazelMessage_377492 COB_009_carta C011_euskera_DazelMessage_377513 COB_009_carta C011_gallego_DazelMessage_377539 | R10: COB_009_carta C011_castellano.afp COB_009_carta C011_catalan_DazelMessage_377492.afp COB_009_carta C011_euskera_DazelMessage_377513.afp COB_009_carta C011_gallego_DazelMessage_377539.afp
A11: Proyecto Compositor Documental - GNCOM | B11: Caso prueba | C11: Nueva | D11: Normal | E11: COB_010 | F11: Generar carta C012__Carta Aviso Corte Electricidad | G11: Cobros | H11: Carta anterior de la tipología C012 Idioma: CA, ES, EU, GA | I11: Se marcan los eventos para reprocesar. Se ejecutan los procesos de procesamiento de eventos. Se ejecuta el proceso de generación de xml. | J11: Se genera el xml. | K11: Revisión OK | L11: Joaquin Pozo | M11: 45662 | N11: 45666 | Q11: DazelMessage_376558_C012_E.xml DazelMessage_376558_C012_E.xml DazelMessage_377160_C012_K.xml DazelMessage_377163_C012_G.xml | R11: DazelMessage_376558_C012_E.afp.pdf DazelMessage_377080_C012_C.afp.pdf DazelMessage_377160_C012_K.afp.pdf DazelMessage_377163_C012_G.afp.pdf
A12: Proyecto Compositor Documental - GNCOM | B12: Caso prueba | C12: Nueva | D12: Normal | E12: COB_011 | F12: Generar carta C013__Carta Aviso Corte GNL | G12: Cobros | H12: Carta anterior de la tipología C013 Idioma: CA, ES, EU, GA | I12: Se marcan los eventos para reprocesar. Se ejecutan los procesos de procesamiento de eventos. Se ejecuta el proceso de generación de xml. | J12: Se genera el xml. | K12: Revisión OK | L12: Joaquin Pozo | M12: 45662 | N12: 45666 | Q12: DazelMessage_376312_C013_E.xml DazelMessage_377161_C013_K.xml DazelMessage_377079_C013_C.xml DazelMessage_377164_C013_G.xml | R12: DazelMessage_376312_C013_E.afp.pdf DazelMessage_377161_C013_K.afp.pdf DazelMessage_377164_C013_G.afp.pdf DazelMessage_377079_C013_C.afp.pdf
A13: Proyecto Compositor Documental - GNCOM | B13: Caso prueba | C13: Nueva | D13: Normal | E13: COB_012 | F13: Generar carta C014__Carta Aviso Rescisión | G13: Cobros | H13: Carta anterior de la tipología C014 Idioma: CA, ES, EU, GA | I13: Se marcan los eventos para reprocesar. Se ejecutan los procesos de procesamiento de eventos. Se ejecuta el proceso de generación de xml. | J13: Se genera el xml. | K13: Revisión OK | L13: Joaquin Pozo | M13: 45662 | N13: 45666 | Q13: DazelMessage_376638_C014.xml DazelMessage_377302_C014_K.xml DazelMessage_376638_C014_C.xml DazelMessage_377298_C014_G.xml | R13: DazelMessage_377302_C014_K.afp.pdf DazelMessage_376638_C014.afp.pdf DazelMessage_377298_C014_G.afp.pdf DazelMessage_376638_C014_C.afp.pdf
A14: Proyecto Compositor Documental - GNCOM | B14: Caso prueba | C14: Nueva | D14: Normal | E14: COB_013 | F14: Generar carta C015__Jurídico | G14: Cobros | H14: Carta anterior de la tipología C015 Idioma: CA, ES, EU, GA | I14: Se marcan los eventos para reprocesar. Se ejecutan los procesos de procesamiento de eventos. Se ejecuta el proceso de generación de xml. | J14: Se genera el xml. | K14: Revisión OK | L14: Joaquin Pozo | M14: 45662 | N14: 45666 | Q14: DazelMessage_376584_C015_C.xml DazelMessage_377219_C015_G.xml DazelMessage_377406_C015_K.xml DazelMessage_376584_C015.xml | R14: DazelMessage_376584_C015.afp.pdf DazelMessage_377219_C015_G.afp.pdf DazelMessage_376584_C015_C.afp.pdf DazelMessage_377406_C015_K.afp.pdf
A15: Proyecto Compositor Documental - GNCOM | B15: Caso prueba | C15: Nueva | D15: Normal | E15: COB_014 | F15: Generar carta C016__Carta de reconocimiento de deuda Mayoristas modelo Impago | G15: Cobros | H15: Carta anterior de la tipología C016 Idioma: CA, ES, EU, GA | I15: Se marcan los eventos para reprocesar. Se ejecutan los procesos de procesamiento de eventos. Se ejecuta el proceso de generación de xml. | J15: Se genera el xml. | K15: Revisión OK | L15: Joaquin Pozo | M15: 45662 | N15: 45666 | Q15: DazelMessage_377458_C016_K.xml DazelMessage_376339_C016_G.xml DazelMessage_376339_C016.xml DazelMessage_377486_C016_C.xml | R15: DazelMessage_377458_C016_K.afp.pdf DazelMessage_376339_C016_G.afp.pdf DazelMessage_377486_C016_C.afp.pdf DazelMessage_376339_C016.afp.pdf
A16: Proyecto Compositor Documental - GNCOM | B16: Caso prueba | C16: Nueva | D16: Normal | E16: COB_015 | F16: Generar carta C017__Carta de reconocimiento de deuda Mayoristas modelo Fact acumulada | G16: Cobros | H16: Carta anterior de la tipología C017 Idioma: CA, ES, EU, GA | I16: Se marcan los eventos para reprocesar. Se ejecutan los procesos de procesamiento de eventos. Se ejecuta el proceso de generación de xml. | J16: Se genera el xml. | K16: Revisión OK | L16: Joaquin Pozo | M16: 45662 | N16: 45666 | Q16: DazelMessage_376637_C017.xml DazelMessage_377485_C017_C.xml DazelMessage_377457_C017_K.xml DazelMessage_376637_C017_G.xml | R16: DazelMessage_376637_C017.afp.pdf DazelMessage_377485_C017_C.afp.pdf DazelMessage_377457_C017_K.afp.pdf DazelMessage_376637_C017_G.afp.pdf
A17: Proyecto Compositor Documental - GNCOM | B17: Caso prueba | C17: Nueva | D17: Normal | E17: COB_016 | F17: Generar carta C018__Carta de reconocimiento de deuda Mayoristas modelo Sin clausulas | G17: Cobros | H17: Carta anterior de la tipología C018 Idioma: CA, ES, EU, GA | I17: Se marcan los eventos para reprocesar. Se ejecutan los procesos de procesamiento de eventos. Se ejecuta el proceso de generación de xml. | J17: Se genera el xml. | K17: Revisión OK | L17: Joaquin Pozo | M17: 45662 | N17: 45666 | Q17: DazelMessage_376340_C018_G.xml DazelMessage_377643_C018_K.xml DazelMessage_376340_C018.xml DazelMessage_377566_C018_C.xml | R17: DazelMessage_376340_C018_G.afp.pdf DazelMessage_377643_C018_K.afp.pdf DazelMessage_377566_C018_C.afp.pdf DazelMessage_376340_C018.afp.pdf
A18: Proyecto Compositor Documental - GNCOM | B18: Caso prueba | C18: Nueva | D18: Normal | E18: COB_017 | F18: Generar carta C019__Carta Intereses de demora | G18: Cobros | H18: Carta anterior de la tipología C019 Idioma: CA, ES, EU, GA | I18: Se marcan los eventos para reprocesar. Se ejecutan los procesos de procesamiento de eventos. Se ejecuta el proceso de generación de xml. | J18: Se genera el xml. | K18: Revisión OK | L18: Joaquin Pozo | M18: 45662 | N18: 45666 | Q18: DazelMessage_377565_C019_G.xml DazelMessage_377617_C019_K.xml DazelMessage_377565_C019_E.xml DazelMessage_377565_C019_C.xml | R18: DazelMessage_377565_C019_E.afp.pdf DazelMessage_377565_C019_C.afp.pdf DazelMessage_377617_C019_K.afp.pdf DazelMessage_377565_C019_G.afp.pdf
P19: =(COUNTIF(P2:P18,"OK")/(COUNTBLANK(P2:P18)+(COUNTA(P2:P18)-(COUNTIF(P2:P18,"N/A"))))) -> 0 | Q19: Porcentaje de Avance
P20: =COUNTBLANK(P2:P18)+(COUNTA(P2:P18)-(COUNTIF(P2:P18,"N/A"))-(COUNTIF(P2:P18,"OK"))-(COUNTIF(P2:P18,"KO"))) -> 17 | Q20: Pendiente
P21: =COUNTIF(P2:P18,"KO") -> 0 | Q21: KO
P22: =COUNTIF(P2:P18,"OK") -> 0 | Q22: OK
P23: =COUNTBLANK(P2:P18)+(COUNTA(P2:P18)-(COUNTIF(P2:P18,"N/A"))) -> 17 | Q23: Total

Sheet Facturas GNCOMP
A1: Proyecto | B1: Tipo | C1: Estado | D1: Prioridad | E1: Codigo de Prueba | F1: Asunto | G1: Módulos Delta | H1: Datos de prueba | I1: Técnica de pruebas | J1: Resultado esperado | K1: COMENTARIOS NEGOCIO | L1: Responsable | M1: Fecha inicio | N1: Fecha Fin | O1: Fecha Liberado | P1: Resultado OK/KO | Q1: xml papyrus | R1: pdf papyrus
A2: Proyecto Compositor Documental - GNCOM | B2: Caso prueba | C2: Nueva | D2: Normal | E2: FAC_001 | F2: Factura Gas Portugal F401-F411 Subformulario Gas Portugal Lectura mensual | G2: FACTURACIÓN | H2: Factura Gas Portugal con Lectura mensual Formulario: F401 Subformulario: F411 Idioma: PT | I2: Impresión facturas en los distintos idiomas | J2: Generación de xml y PDF | K2: Revisión OK | L2: Javi Granadino / Esther Rigo (M. Simón) | M2: 45669 | N2: 45673 | Q2: FAC_001_PT_FT 259800004336.xml | R2: FAC_001_PT_FT_259800004336.afp.pdf
A3: Proyecto Compositor Documental - GNCOM | B3: Caso prueba | C3: Nueva | D3: Normal | E3: FAC_002 | F3: Factura Gas Portugal F401-F421 Subformulario Gas Portugal Lectura diaria con curva | G3: FACTURACIÓN | H3: Factura Gas Portugal con Lectura diaria con curvaFormulario: F401 Subformulario: F421 Idioma: PT | I3: Impresión facturas en los distintos idiomas | J3: Generación de xml y PDF | K3: Revisión OK | L3: Javi Granadino / Esther Rigo (M. Simón) | M3: 45669 | N3: 45673 | Q3: FAC_002_PT_FT 259800003947 | R3: FAC_002_PT_FT 259800003947.pdf
A4: Proyecto Compositor Documental - GNCOM | B4: Caso prueba | C4: Nueva | D4: Normal | E4: FAC_003 | F4: Factura Gas Portugal CV (F401) | G4: FACTURACIÓN | H4: Factura Gas Portugal CV (Cargo Vario) Formulario: F401 Subformulario: N/A Idioma: PT | I4: Impresión facturas en los distintos idiomas | J4: Generación de xml y PDF | K4: Revisión OK | L4: Javi Granadino / Esther Rigo (M. Simón) | M4: 45669 | N4: 45673 | Q4: FAC_003_PT_FT 259300000082.xml | R4: FAC_003_PT_FT 259300000082.pdf
A5: Proyecto Compositor Documental - GNCOM | B5: Caso prueba | C5: Nueva | D5: Normal | E5: FAC_004 | F5: Factura de ajuste Gas Portugal (F401) | G5: FACTURACIÓN | H5: Factura de ajuste Gas Portugal Formulario: F401 Subformulario: F411/F421 Idioma: PT | I5: Impresión facturas en los distintos idiomas | J5: Generación de xml y PDF | K5: Revisión OK | L5: Javi Granadino / Esther Rigo (M. Simón) | M5: 45669 | N5: 45673 | Q5: DazelMessage_378644.xml Este XML contiene: NroOficial Nombre del XML Nombre del PDF Tipo de Cálculo ND 2599/00000078 DazelMessage_378644.xml DazelMessage_378644_F401.afp.pdf Recalculo ND 2589/00000409 DazelMessage_378644.xml DazelMessage_378644_F401.afp.pdf Ajuste NC 2597/00000214 DazelMessage_378644.xml DazelMessage_378644_F401.afp.pdf Anulación | R5: DazelMessage_378644_F401.afp.pdf Detalle de cada documento: ND 2599/00000078 – Factura de Recalculo En el XML: <tipoCalculo>Recalculo</tipoCalculo> Corresponde a una factura normal con recálculo de consumos. ND 2589/00000409 – Nota de Débito de Ajuste En el XML: <tipoCalculo>Ajuste</tipoCalculo> Es una nota de débito que complementa una factura anterior por diferencias en consumos. NC 2597/00000214 – Nota de Crédito de Anulación En el XML: <tipoCalculo>Anulacion</tipoCalculo> Es una nota de crédito que anula y rectifica íntegramente una factura previa.
A6: Proyecto Compositor Documental - GNCOM | B6: Caso prueba | C6: Nueva | D6: Normal | E6: FAC_005 | F6: Factura de recálculo Gas Portugal (F401) | G6: FACTURACIÓN | H6: Factura de recálculo Gas Portugal Formulario: F401 Subformulario:F411/F421 Idioma: PT | I6: Impresión facturas en los distintos idiomas | J6: Generación de xml y PDF | K6: Revisión OK | L6: Javi Granadino / Esther Rigo (M. Simón) | M6: 45669 | N6: 45673 | Q6: DazelMessage_378644.xml Este XML contiene: NroOficial Nombre del XML Nombre del PDF Tipo de Cálculo ND 2599/00000078 DazelMessage_378644.xml DazelMessage_378644_F401.afp.pdf Recalculo ND 2589/00000409 DazelMessage_378644.xml DazelMessage_378644_F401.afp.pdf Ajuste NC 2597/00000214 DazelMessage_378644.xml DazelMessage_378644_F401.afp.pdf Anulación | R6: DazelMessage_378644_F401.afp.pdf Detalle de cada documento: ND 2599/00000078 – Factura de Recalculo En el XML: <tipoCalculo>Recalculo</tipoCalculo> Corresponde a una factura normal con recálculo de consumos. ND 2589/00000409 – Nota de Débito de Ajuste En el XML: <tipoCalculo>Ajuste</tipoCalculo> Es una nota de débito que complementa una factura anterior por diferencias en consumos. NC 2597/00000214 – Nota de Crédito de Anulación En el XML: <tipoCalculo>Anulacion</tipoCalculo> Es una nota de crédito que anula y rectifica íntegramente una factura previa.
A7: Proyecto Compositor Documental - GNCOM | B7: Caso prueba | C7: Nueva | D7: Normal | E7: FAC_006 | F7: Factura de anulación Gas Portugal (F401) | G7: FACTURACIÓN | H7: Factura de anulación Gas Portugal Formulario: F401 Subformulario: F411/F421 Idioma: PT | I7: Impresión facturas en los distintos idiomas | J7: Generación de xml y PDF | K7: Revisión OK | L7: Javi Granadino / Esther Rigo (M. Simón) | M7: 45669 | N7: 45673 | Q7: DazelMessage_378644.xml Este XML contiene: NroOficial Nombre del XML Nombre del PDF Tipo de Cálculo ND 2599/00000078 DazelMessage_378644.xml DazelMessage_378644_F401.afp.pdf Recalculo ND 2589/00000409 DazelMessage_378644.xml DazelMessage_378644_F401.afp.pdf Ajuste NC 2597/00000214 DazelMessage_378644.xml DazelMessage_378644_F401.afp.pdf Anulación | R7: DazelMessage_378644_F401.afp.pdf Detalle de cada documento: ND 2599/00000078 – Factura de Recalculo En el XML: <tipoCalculo>Recalculo</tipoCalculo> Corresponde a una factura normal con recálculo de consumos. ND 2589/00000409 – Nota de Débito de Ajuste En el XML: <tipoCalculo>Ajuste</tipoCalculo> Es una nota de débito que complementa una factura anterior por diferencias en consumos. NC 2597/00000214 – Nota de Crédito de Anulación En el XML: <tipoCalculo>Anulacion</tipoCalculo> Es una nota de crédito que anula y rectifica íntegramente una factura previa.
A8: Proyecto Compositor Documental - GNCOM | B8: Caso prueba | C8: Nueva | D8: Normal | E8: FAC_007 | F8: Factura Electricidad Portugal F402-F412 Subformulario Electricidad Portugal | G8: FACTURACIÓN | H8: Factura Electricidad Portugal Formulario: F402 Subformulario: F412 Idioma: PT | I8: Impresión facturas en los distintos idiomas | J8: Generación de xml y PDF | K8: Revisión OK | L8: Javi Granadino / Esther Rigo (M. Simón) | M8: 45669 | N8: 45673 | Q8: FAC_007_PT_FT 259800004169 | R8: FAC_007_PT_FT 259800004169.pdf
